Workbook

Sheet Instructions
A1: Don't edit column K
A3: If the row is blank refer to the uploaded checklist to see if it is dead or missing.
A4: Please also refer to replanting sheet to see if it was replanted (if so it was dead)
A5: If dead put 0 for height, # of leaves, and base diameter
A6: If missing leave cells blank as they may still be alive
A10: Oak Type
A11: NR = Natural Recruit | C11: Oak Type refers to how it was planted if at all.
A12: S = Seedling
A13: A = Acorn
A15: Treatment
A16: OA = Open Area | C16: Treatment refers to microclimate treatment (where it was planted).
A17: SA = Salvia apiana
A18: DT = Downed Tree
A19: AC = Adult Canopy

Sheet Input1
A1: Page Number | B1: Date Collected | C1: Team | D1: Block | E1: Tag # | F1: Oak Type | G1: Treatment | H1: Seedling Height | I1: # of Leaves on Seedlings | J1: Base Seedling Circumference (cm) | K1: Base Seedling Diameter (mm) | L1: Is Saliva apiana alive? | M1: Notes
A2: Page # | B2: MM/DD/YYYY | C2: Code | D2: # | E2: # | F2: NR, S, or A | G2: AC, OA, SA, NP, or DT | H2: (cm) | I2: # | J2: (cm) | K2: (mm) | L2: Yes, No, or Missing? | M2: as written on data sheet
A3: 1 | B3: 45951 | C3: HH, LS, JA, SM | D3: 1 | E3: 19 | F3: S | G3: AC | H3: 0 | I3: 0 | J3: 0 | K3: =(J3/3.14)*10 -> 0 | M3: 208 new nat recruit
A4: 1 | B4: 45951 | C4: HH, LS, JA, SM | D4: 1 | E4: 20 | F4: S | G4: AC | K4: =(J4/3.14)*10 -> 0
A5: 1 | B5: 45951 | C5: HH, LS, JA, SM | D5: 1 | E5: 21 | F5: S | G5: AC | H5: 0 | I5: 0 | J5: 0 | K5: =(J5/3.14)*10 -> 0
A6: 1 | B6: 45951 | C6: HH, LS, JA, SM | D6: 1 | E6: 16 | F6: S | G6: SA | K6: =(J6/3.14)*10 -> 0 | L6: missing
A7: 1 | B7: 45951 | C7: HH, LS, JA, SM | D7: 1 | E7: 17 | F7: S | G7: SA | K7: =(J7/3.14)*10 -> 0 | L7: missing
A8: 1 | B8: 45951 | C8: HH, LS, JA, SM | D8: 1 | E8: 18 | F8: S | G8: SA | K8: =(J8/3.14)*10 -> 0 | L8: missing
A9: 1 | B9: 45951 | C9: HH, LS, JA, SM | D9: 1 | E9: 14 | F9: A | G9: SA | K9: =(J9/3.14)*10 -> 0 | M9: an acorn germinated
A10: 1 | B10: 45951 | C10: HH, LS, JA, SM | D10: 1 | E10: 11 | F10: A | G10: OA | K10: =(J10/3.14)*10 -> 0 | M10: an acorn germinated
A11: 1 | B11: 45951 | C11: HH, LS, JA, SM | D11: 1 | E11: 7 | F11: S | G11: OA | H11: 17 | I11: 13 | J11: 1 | K11: =(J11/3.14)*10 -> 3.1847134
A12: 1 | B12: 45951 | C12: HH, LS, JA, SM | D12: 1 | E12: 8 | F12: S | G12: OA | K12: =(J12/3.14)*10 -> 0
A13: 1 | B13: 45951 | C13: HH, LS, JA, SM | D13: 1 | E13: 9 | F13: S | G13: OA | H13: 0 | I13: 0 | J13: 0 | K13: =(J13/3.14)*10 -> 0
A14: 2 | B14: 45951 | C14: HH, LS, JA, SM | D14: 1 | E14: 1 | F14: S | G14: DT | K14: =(J14/3.14)*10 -> 0
A15: 2 | B15: 45951 | C15: HH, LS, JA, SM | D15: 1 | E15: 3 | F15: S | G15: DT | K15: =(J15/3.14)*10 -> 0
A16: 2 | B16: 45951 | C16: HH, LS, JA, SM | D16: 1 | E16: 6 | F16: S | G16: DT | H16: 24 | I16: 32 | J16: 1 | K16: =(J16/3.14)*10 -> 3.1847134
A17: 2 | B17: 45951 | C17: HH, LS, JA, SM | D17: 1 | E17: 4 | F17: A | G17: DT | H17: 0 | I17: 0 | J17: 0 | K17: =(J17/3.14)*10 -> 0 | M17: an acorn germinated
A18: 2 | B18: 45951 | C18: HH, LS, JA, SM | D18: 1 | E18: 194 | F18: NR | G18: DT | K18: =(J18/3.14)*10 -> 0 | M18: Naturally Occuring
A19: 2 | B19: 45951 | C19: HH, LS, JA, SM | D19: 1 | E19: 195 | F19: NR | G19: OA | K19: =(J19/3.14)*10 -> 0 | M19: Naturally Occuring
A20: 2 | B20: 45951 | C20: HH, LS, JA, SM | D20: 1 | E20: 193 | F20: NR | G20: AC | K20: =(J20/3.14)*10 -> 0 | M20: Naturally Occuring
A21: 3 | B21: 45951 | C21: LS, HH | D21: 2 | E21: 70 | F21: S | G21: AC | H21: 10 | I21: 3 | J21: 1.5 | K21: =(J21/3.14)*10 -> 4.7770701
A22: 3 | B22: 45951 | C22: LS, HH | D22: 2 | E22: 71 | F22: S | G22: AC | H22: 0 | I22: 0 | J22: 0 | K22: =(J22/3.14)*10 -> 0
A23: 3 | B23: 45951 | C23: LS, HH | D23: 2 | E23: 72 | F23: S | G23: AC | H23: 0 | I23: 0 | J23: 0 | K23: =(J23/3.14)*10 -> 0
A24: 3 | B24: 45951 | C24: LS, HH | D24: 2 | E24: 49 | F24: A | G24: SA | H24: 0 | I24: 0 | J24: 0 | K24: =(J24/3.14)*10 -> 0 | M24: was salvia only
A25: 3 | B25: 45951 | C25: LS, HH | D25: 2 | E25: 50 | F25: A | G25: SA | H25: 0 | I25: 0 | J25: 0 | K25: =(J25/3.14)*10 -> 0 | M25: was salvia only
A26: 3 | B26: 45951 | C26: LS, HH | D26: 2 | E26: 52 | F26: S | G26: SA | H26: 0 | I26: 0 | J26: 0 | K26: =(J26/3.14)*10 -> 0 | M26: was both
A27: 3 | B27: 45951 | C27: LS, HH | D27: 2 | E27: 53 | F27: S | G27: SA | H27: 0 | I27: 0 | J27: 0 | K27: =(J27/3.14)*10 -> 0 | M27: was both
A28: 3 | B28: 45951 | C28: LS, HH | D28: 2 | E28: 54 | F28: S | G28: SA | H28: 0 | I28: 0 | J28: 0 | K28: =(J28/3.14)*10 -> 0 | M28: seedling only
A29: 3 | B29: 45951 | C29: LS, HH | D29: 2 | E29: 56 | F29: A | G29: OA | H29: 0 | I29: 0 | J29: 0 | K29: =(J29/3.14)*10 -> 0 | M29: acorn germinated
A30: 3 | B30: 45951 | C30: LS, HH | D30: 2 | E30: 57 | F30: A | G30: OA | H30: 0 | I30: 0 | J30: 0 | K30: =(J30/3.14)*10 -> 0 | M30: acorn germinated
A31: 3 | B31: 45951 | C31: LS, HH | D31: 2 | E31: 58 | F31: S | G31: OA | H31: 0 | I31: 0 | J31: 0 | K31: =(J31/3.14)*10 -> 0
A32: 3 | B32: 45951 | C32: LS, HH | D32: 2 | E32: 51 | F32: A | G32: SA | H32: 0 | I32: 0 | J32: 0 | K32: =(J32/3.14)*10 -> 0 | M32: salvia alive
A33: 4 | B33: 45951 | C33: LS, HH | D33: 2 | E33: 59 | F33: S | G33: OA | H33: 0 | I33: 0 | J33: 0 | K33: =(J33/3.14)*10 -> 0
A34: 4 | B34: 45951 | C34: LS, HH | D34: 2 | E34: 60 | F34: S | G34: OA | H34: 0 | I34: 0 | J34: 0 | K34: =(J34/3.14)*10 -> 0
A35: 4 | B35: 45951 | C35: LS, HH | D35: 2 | E35: 62 | F35: S | G35: DT | H35: 0 | I35: 0 | J35: 0 | K35: =(J35/3.14)*10 -> 0
A36: 4 | B36: 45951 | C36: LS, HH | D36: 2 | E36: 64 | F36: S | G36: DT | H36: 0 | I36: 0 | J36: 0 | K36: =(J36/3.14)*10 -> 0
A37: 4 | B37: 45951 | C37: LS, HH | D37: 2 | E37: 66 | F37: S | G37: DT | H37: 0 | I37: 0 | J37: 0 | K37: =(J37/3.14)*10 -> 0
A38: 5 | B38: 45951 | C38: SM, LS, HH, JA | D38: 3 | E38: 28 | F38: S | G38: OA | H38: 0 | I38: 0 | J38: 0 | K38: =(J38/3.14)*10 -> 0
A39: 5 | B39: 45951 | C39: SM, LS, HH, JA | D39: 3 | E39: 29 | F39: S | G39: OA | H39: 0 | I39: 0 | J39: 0 | K39: =(J39/3.14)*10 -> 0
A40: 5 | B40: 45951 | C40: SM, LS, HH, JA | D40: 3 | E40: 30 | F40: S | G40: OA | H40: 0 | I40: 0 | J40: 0 | K40: =(J40/3.14)*10 -> 0
...

Sheet Input2
A1: Page Number | B1: Date Collected | C1: Team | D1: Block | E1: Tag # | F1: Oak Type | G1: Treatment | H1: Seedling Height | I1: # of Leaves on Seedlings | J1: Base Seedling Circumference (cm) | K1: Base Seedling Diameter (mm) | L1: Is Saliva apiana alive? | M1: Notes
A2: Page # | B2: MM/DD/YYYY | C2: Code | D2: # | E2: # | F2: NR, S, or A | G2: AC, OA, SA, NP, or DT | H2: (cm) | I2: # | J2: (cm) | K2: (mm) | L2: Yes, No, or Missing? | M2: as written on data sheet
A3: 1 | B3: 45951 | C3: HH, LS, JA, SM | D3: 1 | E3: 19 | F3: S | G3: AC | K3: =(J3/3.14)*10 -> 0
A4: 1 | B4: 45951 | C4: HH, LS, JA, SM | D4: 1 | E4: 20 | F4: S | G4: AC | K4: =(J4/3.14)*10 -> 0
A5: 1 | B5: 45951 | C5: HH, LS, JA, SM | D5: 1 | E5: 21 | F5: S | G5: AC | K5: =(J5/3.14)*10 -> 0
A6: 1 | B6: 45951 | C6: HH, LS, JA, SM | D6: 1 | E6: 16 | F6: S | G6: SA | K6: =(J6/3.14)*10 -> 0 | L6: missing
A7: 1 | B7: 45951 | C7: HH, LS, JA, SM | D7: 1 | E7: 17 | F7: S | G7: SA | K7: =(J7/3.14)*10 -> 0 | L7: missing
A8: 1 | B8: 45951 | C8: HH, LS, JA, SM | D8: 1 | E8: 18 | F8: S | G8: SA | K8: =(J8/3.14)*10 -> 0 | L8: missing
A9: 1 | B9: 45951 | C9: HH, LS, JA, SM | D9: 1 | E9: 14 | F9: A | G9: SA | K9: =(J9/3.14)*10 -> 0 | M9: an acorn germinated
A10: 1 | B10: 45951 | C10: HH, LS, JA, SM | D10: 1 | E10: 11 | F10: A | G10: OA | K10: =(J10/3.14)*10 -> 0 | M10: an acorn germinated
A11: 1 | B11: 45951 | C11: HH, LS, JA, SM | D11: 1 | E11: 7 | F11: S | G11: OA | H11: 17 | I11: 13 | J11: 1 | K11: =(J11/3.14)*10 -> 3.1847134
A12: 1 | B12: 45951 | C12: HH, LS, JA, SM | D12: 1 | E12: 8 | F12: S | G12: OA | K12: =(J12/3.14)*10 -> 0
A13: 1 | B13: 45951 | C13: HH, LS, JA, SM | D13: 1 | E13: 9 | F13: S | G13: OA | K13: =(J13/3.14)*10 -> 0
A14: 2 | B14: 45951 | C14: HH, LS, JA, SM | D14: 1 | E14: 1 | F14: S | G14: DT | K14: =(J14/3.14)*10 -> 0
A15: 2 | B15: 45951 | C15: HH, LS, JA, SM | D15: 1 | E15: 3 | F15: S | G15: DT | K15: =(J15/3.14)*10 -> 0
A16: 2 | B16: 45951 | C16: HH, LS, JA, SM | D16: 1 | E16: 6 | F16: S | G16: DT | H16: 24 | I16: 32 | J16: 1 | K16: =(J16/3.14)*10 -> 3.1847134
A17: 2 | B17: 45951 | C17: HH, LS, JA, SM | D17: 1 | E17: 4 | F17: A | G17: DT | K17: =(J17/3.14)*10 -> 0 | M17: an acorn germinated
A18: 2 | B18: 45951 | C18: HH, LS, JA, SM | D18: 1 | E18: 194 | F18: NR | G18: DT | K18: =(J18/3.14)*10 -> 0
A19: 2 | B19: 45951 | C19: HH, LS, JA, SM | D19: 1 | E19: 195 | F19: NR | G19: OA | K19: =(J19/3.14)*10 -> 0 | M19: Naturally Occuring
A20: 2 | B20: 45951 | C20: HH, LS, JA, SM | D20: 1 | E20: 193 | F20: NR | G20: AC | K20: =(J20/3.14)*10 -> 0 | M20: Naturally Occuring
A21: 3 | B21: 45951 | C21: LS, HH | D21: 2 | E21: 70 | F21: S | G21: AC | H21: 10 | I21: 3 | J21: 1.5 | K21: =(J21/3.14)*10 -> 4.7770701
A22: 3 | B22: 45951 | C22: LS, HH | D22: 2 | E22: 71 | F22: S | G22: AC | K22: =(J22/3.14)*10 -> 0
A23: 3 | B23: 45951 | C23: LS, HH | D23: 2 | E23: 72 | F23: S | G23: AC | K23: =(J23/3.14)*10 -> 0
A24: 3 | B24: 45951 | C24: LS, HH | D24: 2 | E24: 49 | F24: A | G24: SA | K24: =(J24/3.14)*10 -> 0 | M24: Was salvia only
A25: 3 | B25: 45951 | C25: LS, HH | D25: 2 | E25: 50 | F25: A | G25: SA | K25: =(J25/3.14)*10 -> 0 | M25: Was salvia only
A26: 3 | B26: 45951 | C26: LS, HH | D26: 2 | E26: 52 | F26: S | G26: SA | K26: =(J26/3.14)*10 -> 0 | M26: Was both
A27: 3 | B27: 45951 | C27: LS, HH | D27: 2 | E27: 53 | F27: S | G27: SA | K27: =(J27/3.14)*10 -> 0 | M27: Was both
A28: 3 | B28: 45951 | C28: LS, HH | D28: 2 | E28: 54 | F28: S | G28: SA | K28: =(J28/3.14)*10 -> 0 | M28: seedling only
A29: 3 | B29: 45951 | C29: LS, HH | D29: 2 | E29: 56 | F29: A | G29: OA | K29: =(J29/3.14)*10 -> 0 | M29: acorn germinated
A30: 3 | B30: 45951 | C30: LS, HH | D30: 2 | E30: 57 | F30: A | G30: OA | K30: =(J30/3.14)*10 -> 0 | M30: acorn germinated
A31: 3 | B31: 45951 | C31: LS, HH | D31: 2 | E31: 58 | F31: S | G31: OA | K31: =(J31/3.14)*10 -> 0
A32: 3 | B32: 45951 | C32: LS, HH | D32: 2 | E32: 51 | F32: A | G32: SA | K32: =(J32/3.14)*10 -> 0 | M32: Salvia alive
A33: 4 | B33: 45951 | C33: LS, HH | D33: 2 | E33: 59 | F33: S | G33: OA | K33: =(J33/3.14)*10 -> 0
A34: 4 | B34: 45951 | C34: LS, HH | D34: 2 | E34: 60 | F34: S | G34: OA | K34: =(J34/3.14)*10 -> 0
A35: 4 | B35: 45951 | C35: LS, HH | D35: 2 | E35: 62 | F35: S | G35: DT | K35: =(J35/3.14)*10 -> 0
A36: 4 | B36: 45951 | C36: LS, HH | D36: 2 | E36: 64 | F36: S | G36: DT | K36: =(J36/3.14)*10 -> 0
A37: 4 | B37: 45951 | C37: LS, HH | D37: 2 | E37: 66 | F37: S | G37: DT | K37: =(J37/3.14)*10 -> 0
A38: 5 | B38: 45951 | C38: SM, LS, HH, JA | D38: 3 | E38: 28 | F38: S | G38: OA | K38: =(J38/3.14)*10 -> 0
A39: 5 | B39: 45951 | C39: SM, LS, HH, JA | D39: 3 | E39: 29 | F39: S | G39: OA | K39: =(J39/3.14)*10 -> 0
A40: 5 | B40: 45951 | C40: SM, LS, HH, JA | D40: 3 | E40: 30 | F40: S | G40: OA | K40: =(J40/3.14)*10 -> 0
...

Sheet Validation
A1: =if(Input1!A1=Input2!A1, Input1!A1, "ERROR") -> Page Number | B1: =if(Input1!B1=Input2!B1, Input1!B1, "ERROR") -> Date Collected | C1: =if(Input1!C1=Input2!C1, Input1!C1, "ERROR") -> Team | D1: =if(Input1!D1=Input2!D1, Input1!D1, "ERROR") -> Block | E1: =if(Input1!E1=Input2!E1, Input1!E1, "ERROR") -> Tag # | F1: =if(Input1!F1=Input2!F1, Input1!F1, "ERROR") -> Oak Type | G1: =if(Input1!G1=Input2!G1, Input1!G1, "ERROR") -> Treatment | H1: =if(Input1!H1=Input2!H1, Input1!H1, "ERROR") -> Seedling Height | ... M1: =if(Input1!M1=Input2!M1, Input1!M1, "ERROR") -> Notes | N1: =if(Input1!O1=Input2!N1, Input1!O1, "ERROR") | O1: =if(Input1!P1=Input2!O1, Input1!P1, "ERROR") | P1: =if(Input1!Q1=Input2!P1, Input1!Q1, "ERROR") | Q1: =if(Input1!R1=Input2!Q1, Input1!R1, "ERROR") | R1: =if(Input1!S1=Input2!R1, Input1!S1, "ERROR") | S1: =if(Input1!T1=Input2!S1, Input1!T1, "ERROR")
A2: =if(Input1!A2=Input2!A2, Input1!A2, "ERROR") -> Page # | B2: =if(Input1!B2=Input2!B2, Input1!B2, "ERROR") -> MM/DD/YYYY | C2: =if(Input1!C2=Input2!C2, Input1!C2, "ERROR") -> Code | D2: =if(Input1!D2=Input2!D2, Input1!D2, "ERROR") -> # | E2: =if(Input1!E2=Input2!E2, Input1!E2, "ERROR") -> # | F2: =if(Input1!F2=Input2!F2, Input1!F2, "ERROR") -> NR, S, or A | G2: =if(Input1!G2=Input2!G2, Input1!G2, "ERROR") -> AC, OA, SA, NP, or DT | H2: =if(Input1!H2=Input2!H2, Input1!H2, "ERROR") -> (cm) | ... M2: =if(Input1!M2=Input2!M2, Input1!M2, "ERROR") -> as written on data sheet
A3: =if(Input1!A3=Input2!A3, Input1!A3, "ERROR") -> 1 | B3: =if(Input1!B3=Input2!B3, Input1!B3, "ERROR") -> 45951 | C3: =if(Input1!C3=Input2!C3, Input1!C3, "ERROR") -> HH, LS, JA, SM | D3: =if(Input1!D3=Input2!D3, Input1!D3, "ERROR") -> 1 | E3: =if(Input1!E3=Input2!E3, Input1!E3, "ERROR") -> 19 | F3: =if(Input1!F3=Input2!F3, Input1!F3, "ERROR") -> S | G3: =if(Input1!G3=Input2!G3, Input1!G3, "ERROR") -> AC | H3: =if(Input1!H3=Input2!H3, Input1!H3, "ERROR") -> 0 | ... L3: =if(Input1!L3=Input2!L3, Input1!L3, "ERROR")
A4: =if(Input1!A4=Input2!A4, Input1!A4, "ERROR") -> 1 | B4: =if(Input1!B4=Input2!B4, Input1!B4, "ERROR") -> 45951 | C4: =if(Input1!C4=Input2!C4, Input1!C4, "ERROR") -> HH, LS, JA, SM | D4: =if(Input1!D4=Input2!D4, Input1!D4, "ERROR") -> 1 | E4: =if(Input1!E4=Input2!E4, Input1!E4, "ERROR") -> 20 | F4: =if(Input1!F4=Input2!F4, Input1!F4, "ERROR") -> S | G4: =if(Input1!G4=Input2!G4, Input1!G4, "ERROR") -> AC | H4: =if(Input1!H4=Input2!H4, Input1!H4, "ERROR") | ... L4: =if(Input1!L4=Input2!L4, Input1!L4, "ERROR")
A5: =if(Input1!A5=Input2!A5, Input1!A5, "ERROR") -> 1 | B5: =if(Input1!B5=Input2!B5, Input1!B5, "ERROR") -> 45951 | C5: =if(Input1!C5=Input2!C5, Input1!C5, "ERROR") -> HH, LS, JA, SM | D5: =if(Input1!D5=Input2!D5, Input1!D5, "ERROR") -> 1 | E5: =if(Input1!E5=Input2!E5, Input1!E5, "ERROR") -> 21 | F5: =if(Input1!F5=Input2!F5, Input1!F5, "ERROR") -> S | G5: =if(Input1!G5=Input2!G5, Input1!G5, "ERROR") -> AC | H5: =if(Input1!H5=Input2!H5, Input1!H5, "ERROR") -> 0 | ... L5: =if(Input1!L5=Input2!L5, Input1!L5, "ERROR")
A6: =if(Input1!A6=Input2!A6, Input1!A6, "ERROR") -> 1 | B6: =if(Input1!B6=Input2!B6, Input1!B6, "ERROR") -> 45951 | C6: =if(Input1!C6=Input2!C6, Input1!C6, "ERROR") -> HH, LS, JA, SM | D6: =if(Input1!D6=Input2!D6, Input1!D6, "ERROR") -> 1 | E6: =if(Input1!E6=Input2!E6, Input1!E6, "ERROR") -> 16 | F6: =if(Input1!F6=Input2!F6, Input1!F6, "ERROR") -> S | G6: =if(Input1!G6=Input2!G6, Input1!G6, "ERROR") -> SA | H6: =if(Input1!H6=Input2!H6, Input1!H6, "ERROR") | ... L6: =if(Input1!L6=Input2!L6, Input1!L6, "ERROR") -> missing
A7: =if(Input1!A7=Input2!A7, Input1!A7, "ERROR") -> 1 | B7: =if(Input1!B7=Input2!B7, Input1!B7, "ERROR") -> 45951 | C7: =if(Input1!C7=Input2!C7, Input1!C7, "ERROR") -> HH, LS, JA, SM | D7: =if(Input1!D7=Input2!D7, Input1!D7, "ERROR") -> 1 | E7: =if(Input1!E7=Input2!E7, Input1!E7, "ERROR") -> 17 | F7: =if(Input1!F7=Input2!F7, Input1!F7, "ERROR") -> S | G7: =if(Input1!G7=Input2!G7, Input1!G7, "ERROR") -> SA | H7: =if(Input1!H7=Input2!H7, Input1!H7, "ERROR") | ... L7: =if(Input1!L7=Input2!L7, Input1!L7, "ERROR") -> missing
A8: =if(Input1!A8=Input2!A8, Input1!A8, "ERROR") -> 1 | B8: =if(Input1!B8=Input2!B8, Input1!B8, "ERROR") -> 45951 | C8: =if(Input1!C8=Input2!C8, Input1!C8, "ERROR") -> HH, LS, JA, SM | D8: =if(Input1!D8=Input2!D8, Input1!D8, "ERROR") -> 1 | E8: =if(Input1!E8=Input2!E8, Input1!E8, "ERROR") -> 18 | F8: =if(Input1!F8=Input2!F8, Input1!F8, "ERROR") -> S | G8: =if(Input1!G8=Input2!G8, Input1!G8, "ERROR") -> SA | H8: =if(Input1!H8=Input2!H8, Input1!H8, "ERROR") | ... L8: =if(Input1!L8=Input2!L8, Input1!L8, "ERROR") -> missing
A9: =if(Input1!A9=Input2!A9, Input1!A9, "ERROR") -> 1 | B9: =if(Input1!B9=Input2!B9, Input1!B9, "ERROR") -> 45951 | C9: =if(Input1!C9=Input2!C9, Input1!C9, "ERROR") -> HH, LS, JA, SM | D9: =if(Input1!D9=Input2!D9, Input1!D9, "ERROR") -> 1 | E9: =if(Input1!E9=Input2!E9, Input1!E9, "ERROR") -> 14 | F9: =if(Input1!F9=Input2!F9, Input1!F9, "ERROR") -> A | G9: =if(Input1!G9=Input2!G9, Input1!G9, "ERROR") -> SA | H9: =if(Input1!H9=Input2!H9, Input1!H9, "ERROR") | ... L9: =if(Input1!L9=Input2!L9, Input1!L9, "ERROR")
A10: =if(Input1!A10=Input2!A10, Input1!A10, "ERROR") -> 1 | B10: =if(Input1!B10=Input2!B10, Input1!B10, "ERROR") -> 45951 | C10: =if(Input1!C10=Input2!C10, Input1!C10, "ERROR") -> HH, LS, JA, SM | D10: =if(Input1!D10=Input2!D10, Input1!D10, "ERROR") -> 1 | E10: =if(Input1!E10=Input2!E10, Input1!E10, "ERROR") -> 11 | F10: =if(Input1!F10=Input2!F10, Input1!F10, "ERROR") -> A | G10: =if(Input1!G10=Input2!G10, Input1!G10, "ERROR") -> OA | H10: =if(Input1!H10=Input2!H10, Input1!H10, "ERROR") | ... L10: =if(Input1!L10=Input2!L10, Input1!L10, "ERROR")
A11: =if(Input1!A11=Input2!A11, Input1!A11, "ERROR") -> 1 | B11: =if(Input1!B11=Input2!B11, Input1!B11, "ERROR") -> 45951 | C11: =if(Input1!C11=Input2!C11, Input1!C11, "ERROR") -> HH, LS, JA, SM | D11: =if(Input1!D11=Input2!D11, Input1!D11, "ERROR") -> 1 | E11: =if(Input1!E11=Input2!E11, Input1!E11, "ERROR") -> 7 | F11: =if(Input1!F11=Input2!F11, Input1!F11, "ERROR") -> S | G11: =if(Input1!G11=Input2!G11, Input1!G11, "ERROR") -> OA | H11: =if(Input1!H11=Input2!H11, Input1!H11, "ERROR") -> 17 | ... L11: =if(Input1!L11=Input2!L11, Input1!L11, "ERROR")
A12: =if(Input1!A12=Input2!A12, Input1!A12, "ERROR") -> 1 | B12: =if(Input1!B12=Input2!B12, Input1!B12, "ERROR") -> 45951 | C12: =if(Input1!C12=Input2!C12, Input1!C12, "ERROR") -> HH, LS, JA, SM | D12: =if(Input1!D12=Input2!D12, Input1!D12, "ERROR") -> 1 | E12: =if(Input1!E12=Input2!E12, Input1!E12, "ERROR") -> 8 | F12: =if(Input1!F12=Input2!F12, Input1!F12, "ERROR") -> S | G12: =if(Input1!G12=Input2!G12, Input1!G12, "ERROR") -> OA | H12: =if(Input1!H12=Input2!H12, Input1!H12, "ERROR") | ... L12: =if(Input1!L12=Input2!L12, Input1!L12, "ERROR")
A13: =if(Input1!A13=Input2!A13, Input1!A13, "ERROR") -> 1 | B13: =if(Input1!B13=Input2!B13, Input1!B13, "ERROR") -> 45951 | C13: =if(Input1!C13=Input2!C13, Input1!C13, "ERROR") -> HH, LS, JA, SM | D13: =if(Input1!D13=Input2!D13, Input1!D13, "ERROR") -> 1 | E13: =if(Input1!E13=Input2!E13, Input1!E13, "ERROR") -> 9 | F13: =if(Input1!F13=Input2!F13, Input1!F13, "ERROR") -> S | G13: =if(Input1!G13=Input2!G13, Input1!G13, "ERROR") -> OA | H13: =if(Input1!H13=Input2!H13, Input1!H13, "ERROR") -> 0 | ... L13: =if(Input1!L13=Input2!L13, Input1!L13, "ERROR")
A14: =if(Input1!A14=Input2!A14, Input1!A14, "ERROR") -> 2 | B14: =if(Input1!B14=Input2!B14, Input1!B14, "ERROR") -> 45951 | C14: =if(Input1!C14=Input2!C14, Input1!C14, "ERROR") -> HH, LS, JA, SM | D14: =if(Input1!D14=Input2!D14, Input1!D14, "ERROR") -> 1 | E14: =if(Input1!E14=Input2!E14, Input1!E14, "ERROR") -> 1 | F14: =if(Input1!F14=Input2!F14, Input1!F14, "ERROR") -> S | G14: =if(Input1!G14=Input2!G14, Input1!G14, "ERROR") -> DT | H14: =if(Input1!H14=Input2!H14, Input1!H14, "ERROR") | ... L14: =if(Input1!L14=Input2!L14, Input1!L14, "ERROR")
... A132: =if(Input1!A132=Input2!A132, Input1!A132, "ERROR") -> 15 | B132: =if(Input1!B132=Input2!B132, Input1!B132, "ERROR") -> 45951 | C132: =if(Input1!C132=Input2!C132, Input1!C132, "ERROR") -> EH, HH, JA, SM, LS | D132: =if(Input1!D132=Input2!D132, Input1!D132, "ERROR") -> 8 | E132: =if(Input1!E132=Input2!E132, Input1!E132, "ERROR") -> 189 | F132: =if(Input1!F132=Input2!F132, Input1!F132, "ERROR") -> S | G132: =if(Input1!G132=Input2!G132, Input1!G132, "ERROR") -> SA | H132: =if(Input1!H132=Input2!H132, Input1!H132, "ERROR") -> 0 | ... L132: =if(Input1!L132=Input2!L132, Input1!L132, "ERROR")
A133: =if(Input1!A133=Input2!A133, Input1!A133, "ERROR") -> 15 | B133: =if(Input1!B133=Input2!B133, Input1!B133, "ERROR") -> 45951 | C133: =if(Input1!C133=Input2!C133, Input1!C133, "ERROR") -> ERROR | D133: =if(Input1!D133=Input2!D133, Input1!D133, "ERROR") -> 8 | E133: =if(Input1!E133=Input2!E133, Input1!E133, "ERROR") -> 191 | F133: =if(Input1!F133=Input2!F133, Input1!F133, "ERROR") -> S | G133: =if(Input1!G133=Input2!G133, Input1!G133, "ERROR") -> SA | H133: =if(Input1!H133=Input2!H133, Input1!H133, "ERROR") -> 0 | ... K133: =if(Input1!K133=Input2!K133, Input1!K133, "ERROR") -> 0 | L133: =if(Input1!L133=#REF!, Input1!L133, "ERROR") -> #REF!
A134: =if(Input1!A134=Input2!A134, Input1!A134, "ERROR") -> 15 | B134: =if(Input1!B134=Input2!B134, Input1!B134, "ERROR") -> 45951 | C134: =if(Input1!C134=Input2!C134, Input1!C134, "ERROR") -> EH, JA, LS, SM, HH | D134: =if(Input1!D134=Input2!D134, Input1!D134, "ERROR") -> 8 | E134: =if(Input1!E134=Input2!E134, Input1!E134, "ERROR") -> 192 | F134: =if(Input1!F134=Input2!F134, Input1!F134, "ERROR") -> S | G134: =if(Input1!G134=Input2!G134, Input1!G134, "ERROR") -> SA | H134: =if(Input1!H134=Input2!H134, Input1!H134, "ERROR") -> 87 | ... K134: =if(Input1!K134=Input2!K134, Input1!K134, "ERROR") -> 12.738853 | L134: =if(Input1!L134=Input2!L133, Input1!L134, "ERROR")
A135: =if(Input1!A135=Input2!A135, Input1!A135, "ERROR") -> 15 | B135: =if(Input1!B135=Input2!B135, Input1!B135, "ERROR") -> 45951 | C135: =if(Input1!C135=Input2!C135, Input1!C135, "ERROR") -> EH, JA, LS, SM, HH | D135: =if(Input1!D135=Input2!D135, Input1!D135, "ERROR") -> 8 | E135: =if(Input1!E135=Input2!E135, Input1!E135, "ERROR") -> 180 | F135: =if(Input1!F135=Input2!F135, Input1!F135, "ERROR") -> S | G135: =if(Input1!G135=Input2!G135, Input1!G135, "ERROR") -> OA | H135: =if(Input1!H135=Input2!H135, Input1!H135, "ERROR") -> 0 | ... K135: =if(Input1!K135=Input2!K135, Input1!K135, "ERROR") -> 0 | L135: =if(Input1!L135=Input2!L134, Input1!L135, "ERROR")
A136: =if(Input1!A136=Input2!A136, Input1!A136, "ERROR") -> 15 | B136: =if(Input1!B136=Input2!B136, Input1!B136, "ERROR") -> 45951 | C136: =if(Input1!C136=Input2!C136, Input1!C136, "ERROR") -> EH, JA, LS, SM, HH | D136: =if(Input1!D136=Input2!D136, Input1!D136, "ERROR") -> 8 | E136: =if(Input1!E136=Input2!E136, Input1!E136, "ERROR") -> 181 | F136: =if(Input1!F136=Input2!F136, Input1!F136, "ERROR") -> S | G136: =if(Input1!G136=Input2!G136, Input1!G136, "ERROR") -> OA | H136: =if(Input1!H136=Input2!H136, Input1!H136, "ERROR") | ... K136: =if(Input1!K136=Input2!K136, Input1!K136, "ERROR") -> 0 | L136: =if(Input1!L136=Input2!L135, Input1!L136, "ERROR")
A137: =if(Input1!A137=Input2!A137, Input1!A137, "ERROR") -> 15 | B137: =if(Input1!B137=Input2!B137, Input1!B137, "ERROR") -> 45951 | C137: =if(Input1!C137=Input2!C137, Input1!C137, "ERROR") -> EH, JA, LS, SM, HH | D137: =if(Input1!D137=Input2!D137, Input1!D137, "ERROR") -> 8 | E137: =if(Input1!E137=Input2!E137, Input1!E137, "ERROR") -> 183 | F137: =if(Input1!F137=Input2!F137, Input1!F137, "ERROR") -> S | G137: =if(Input1!G137=Input2!G137, Input1!G137, "ERROR") -> OA | H137: =if(Input1!H137=Input2!H137, Input1!H137, "ERROR") | ... K137: =if(Input1!K137=Input2!K137, Input1!K137, "ERROR") -> 0 | L137: =if(Input1!L137=Input2!L136, Input1!L137, "ERROR")
A138: =if(Input1!A138=Input2!A138, Input1!A138, "ERROR") -> 15 | B138: =if(Input1!B138=Input2!B138, Input1!B138, "ERROR") -> 45951 | C138: =if(Input1!C138=Input2!C138, Input1!C138, "ERROR") -> EH, JA, LS, SM, HH | D138: =if(Input1!D138=Input2!D138, Input1!D138, "ERROR") -> 8 | E138: =if(Input1!E138=Input2!E138, Input1!E138, "ERROR") -> 169 | F138: =if(Input1!F138=Input2!F138, Input1!F138, "ERROR") -> S | G138: =if(Input1!G138=Input2!G138, Input1!G138, "ERROR") -> AC | H138: =if(Input1!H138=Input2!H138, Input1!H138, "ERROR") -> 0 | ... K138: =if(Input1!K138=Input2!K138, Input1!K138, "ERROR") -> 0 | L138: =if(Input1!L138=Input2!L137, Input1!L138, "ERROR")
A139: =if(Input1!A139=Input2!A139, Input1!A139, "ERROR") -> 15 | B139: =if(Input1!B139=Input2!B139, Input1!B139, "ERROR") -> 45951 | C139: =if(Input1!C139=Input2!C139, Input1!C139, "ERROR") -> EH, JA, LS, SM, HH | D139: =if(Input1!D139=Input2!D139, Input1!D139, "ERROR") -> 8 | E139: =if(Input1!E139=Input2!E139, Input1!E139, "ERROR") -> 170 | F139: =if(Input1!F139=Input2!F139, Input1!F139, "ERROR") -> S | G139: =if(Input1!G139=Input2!G139, Input1!G139, "ERROR") -> AC | H139: =if(Input1!H139=Input2!H139, Input1!H139, "ERROR") -> 0 | ... K139: =if(Input1!K139=Input2!K139, Input1!K139, "ERROR") -> 0 | L139: =if(Input1!L139=Input2!L138, Input1!L139, "ERROR")
A140: =if(Input1!A140=Input2!A140, Input1!A140, "ERROR") -> 15 | B140: =if(Input1!B140=Input2!B140, Input1!B140, "ERROR") -> 45951 | C140: =if(Input1!C140=Input2!C140, Input1!C140, "ERROR") -> EH, JA, LS, SM, HH | D140: =if(Input1!D140=Input2!D140, Input1!D140, "ERROR") -> 8 | E140: =if(Input1!E140=Input2!E140, Input1!E140, "ERROR") -> 190A2 | F140: =if(Input1!F140=Input2!F140, Input1!F140, "ERROR") -> A | G140: =if(Input1!G140=Input2!G140, Input1!G140, "ERROR") -> SA | H140: =if(Input1!H140=Input2!H140, Input1!H140, "ERROR") -> 84 | ... K140: =if(Input1!K140=Input2!K140, Input1!K140, "ERROR") -> 13.057325 | L140: =if(Input1!L140=Input2!L139, Input1!L140, "ERROR")
A141: =if(Input1!A141=Input2!A141, Input1!A141, "ERROR") -> 15 | B141: =if(Input1!B141=Input2!B141, Input1!B141, "ERROR") -> 45951 | C141: =if(Input1!C141=Input2!C141, Input1!C141, "ERROR") -> EH, JA, LS, SM, HH | D141: =if(Input1!D141=Input2!D141, Input1!D141, "ERROR") -> 8 | E141: =if(Input1!E141=Input2!E141, Input1!E141, "ERROR") -> 190A1 | F141: =if(Input1!F141=Input2!F141, Input1!F141, "ERROR") -> A | G141: =if(Input1!G141=Input2!G141, Input1!G141, "ERROR") -> SA | H141: =if(Input1!H141=Input2!H141, Input1!H141, "ERROR") -> 121 | ... K141: =if(Input1!K141=Input2!K141, Input1!K141, "ERROR") -> 12.101911 | L141: =if(Input1!L141=Input2!L140, Input1!L141, "ERROR")
A142: =if(Input1!A142=Input2!A142, Input1!A142, "ERROR") -> 16 | B142: =if(Input1!B142=Input2!B142, Input1!B142, "ERROR") -> 45951 | C142: =if(Input1!C142=Input2!C142, Input1!C142, "ERROR") -> EH, JA, LS, SM, HH | D142: =if(Input1!D142=Input2!D142, Input1!D142, "ERROR") -> 8 | E142: =if(Input1!E142=Input2!E142, Input1!E142, "ERROR") -> 171 | F142: =if(Input1!F142=Input2!F142, Input1!F142, "ERROR") -> S | G142: =if(Input1!G142=Input2!G142, Input1!G142, "ERROR") -> AC | H142: =if(Input1!H142=Input2!H142, Input1!H142, "ERROR") -> 0 | ... K142: =if(Input1!K142=Input2!K142, Input1!K142, "ERROR") -> 0 | L142: =if(Input1!L142=Input2!L141, Input1!L142, "ERROR")
A143: =if(Input1!A143=Input2!A143, Input1!A143, "ERROR") -> 16 | B143: =if(Input1!B143=Input2!B143, Input1!B143, "ERROR") -> 45951 | C143: =if(Input1!C143=Input2!C143, Input1!C143, "ERROR") -> EH, JA, LS, SM, HH | D143: =if(Input1!D143=Input2!D143, Input1!D143, "ERROR") -> 8 | E143: =if(Input1!E143=Input2!E143, Input1!E143, "ERROR") -> 175 | F143: =if(Input1!F143=Input2!F143, Input1!F143, "ERROR") -> S | G143: =if(Input1!G143=Input2!G143, Input1!G143, "ERROR") -> DT | H143: =if(Input1!H143=Input2!H143, Input1!H143, "ERROR") -> 0 | ... K143: =if(Input1!K143=Input2!K143, Input1!K143, "ERROR") -> 0 | L143: =if(Input1!L143=Input2!L142, Input1!L143, "ERROR")
A144: =if(Input1!A144=Input2!A144, Input1!A144, "ERROR") -> 16 | B144: =if(Input1!B144=Input2!B144, Input1!B144, "ERROR") -> 45951 | C144: =if(Input1!C144=Input2!C144, Input1!C144, "ERROR") -> EH, JA, LS, SM, HH | D144: =if(Input1!D144=Input2!D144, Input1!D144, "ERROR") -> 8 | E144: =if(Input1!E144=Input2!E144, Input1!E144, "ERROR") -> 177 | F144: =if(Input1!F144=Input2!F144, Input1!F144, "ERROR") -> S | G144: =if(Input1!G144=Input2!G144, Input1!G144, "ERROR") -> DT | H144: =if(Input1!H144=Input2!H144, Input1!H144, "ERROR") -> 0 | ... K144: =if(Input1!K144=Input2!K144, Input1!K144, "ERROR") -> 0 | L144: =if(Input1!L144=Input2!L143, Input1!L144, "ERROR")
A145: =if(Input1!A145=Input2!A145, Input1!A145, "ERROR") -> 16 | B145: =if(Input1!B145=Input2!B145, Input1!B145, "ERROR") -> 45951 | C145: =if(Input1!C145=Input2!C145, Input1!C145, "ERROR") -> EH, JA, LS, SM, HH | D145: =if(Input1!D145=Input2!D145, Input1!D145, "ERROR") -> 8 | E145: =if(Input1!E145=Input2!E145, Input1!E145, "ERROR") -> 182A1 | F145: =if(Input1!F145=Input2!F145, Input1!F145, "ERROR") -> A | G145: =if(Input1!G145=Input2!G145, Input1!G145, "ERROR") -> DT | H145: =if(Input1!H145=Input2!H145, Input1!H145, "ERROR") -> 29 | ... K145: =if(Input1!K145=Input2!K145, Input1!K145, "ERROR") -> 2.388535 | L145: =if(Input1!L145=Input2!L144, Input1!L145, "ERROR")
... A151: =if(Input1!A151=Input2!A151, Input1!A151, "ERROR") | B151: =if(Input1!B151=Input2!B151, Input1!B151, "ERROR") | C151: =if(Input1!C151=Input2!C151, Input1!C151, "ERROR") | D151: =if(Input1!D151=Input2!D151, Input1!D151, "ERROR") | E151: =if(Input1!E151=Input2!E151, Input1!E151, "ERROR") | F151: =if(Input1!F151=Input2!F151, Input1!F151, "ERROR") | G151: =if(Input1!G151=Input2!G151, Input1!G151, "ERROR") | H151: =if(Input1!H151=Input2!H151, Input1!H151, "ERROR") | ... K151: =if(Input1!K151=Input2!K151, Input1!K151, "ERROR") -> 0 | L151: =if(Input1!L151=Input2!L150, Input1!L151, "ERROR")
A152: =if(Input1!A152=Input2!A151, Input1!A152, "ERROR") | B152: =if(Input1!B152=Input2!B151, Input1!B152, "ERROR") | C152: =if(Input1!C152=Input2!C151, Input1!C152, "ERROR") | D152: =if(Input1!D152=Input2!D151, Input1!D152, "ERROR") | E152: =if(Input1!E152=Input2!E151, Input1!E152, "ERROR") | F152: =if(Input1!F152=Input2!F151, Input1!F152, "ERROR") | G152: =if(Input1!G152=Input2!G151, Input1!G152, "ERROR") | H152: =if(Input1!H152=Input2!H151, Input1!H152, "ERROR") | ... L152: =if(Input1!L152=Input2!L151, Input1!L152, "ERROR")
L153: =if(Input1!L153=Input2!L152, Input1!L153, "ERROR")
L154: =if(Input1!L154=Input2!L153, Input1!L154, "ERROR")
L155: =if(Input1!L155=Input2!L154, Input1!L155, "ERROR")
L156: =if(Input1!L156=Input2!L155, Input1!L156, "ERROR")
L157: =if(Input1!L157=Input2!L156, Input1!L157, "ERROR")
L158: =if(Input1!L158=Input2!L157, Input1!L158, "ERROR")
L159: =if(Input1!L159=Input2!L158, Input1!L159, "ERROR")
L160: =if(Input1!L160=Input2!L159, Input1!L160, "ERROR")
L161: =if(Input1!L161=Input2!L160, Input1!L161, "ERROR")
L162: =if(Input1!L162=Input2!L161, Input1!L162, "ERROR")
...
